<?xml version='1.0'?>
<robot name="shelfino">

  <static>false</static>
  <link name='base_link'>
    <!--<pose>0 0 .25 0 0 0</pose>-->
    <origin rpy='0 0 0' xyz='0 0 .25'/>
  

    <collision name='collision'>
      <geometry>
        <box size=".5 .5 .4">
          <!-- <size>.5 .5 .4</size> -->
        </box>
      </geometry>
    </collision>

    <visual name='visual'>
      <origin xyz="0 0 .25"/>
      <geometry>
        <box size=".5 .5 .4">
          <!-- <size>.5 .5 .4</size> -->
        </box>
      </geometry>

      <material name="chassis_blue">
        <color rgba="0.15 0.15 0.85 1"/>
      </material>
      <!-- <material>
        <ambient>0.15 0.15 0.85 1</ambient>
        <diffuse>0.2 0.2 0.92 1</diffuse>
        <specular>0.25 0.25 0.97 1</specular>
        <emissive>0.01 0.01 0.01 1</emissive>
      </material> -->

    </visual>

    <collision name='caster_collision_1'>
      <!-- <pose>-0.2 0 -0.225 0 0 0</pose> -->
      <origin rpy='0 0 0' xyz='-0.2 0 -0.225'/>
      <geometry>
        <box size=".1 .1 .05">
          <!-- <size>.1 .1 .05</size> -->
        </box>
      </geometry>

      <surface>
        <friction>
          <ode>
            <mu>0.0</mu>
            <mu2>0.0</mu2>
            <slip1>0.0</slip1>
            <slip2>0.0</slip2>
          </ode>
        </friction>
      </surface>
    </collision>

    <visual name='caster_visual_1'>
      <!-- <pose>-0.2 0 -0.2 0 0 0</pose> -->
      <origin rpy='0 0 0' xyz='-0.2 0 0.05'/>
      <geometry>
        <sphere radius=".05">
          <!-- <radius>.05</radius> -->
        </sphere>
      </geometry>
      <material name="caster_gray">
        <color rgba="0.15 0.15 0.15 1"/>
      </material>
      <!-- <material>
        <ambient>0.15 0.15 0.15 1</ambient>
        <diffuse>0.25 0.25 0.25 1</diffuse>
        <specular>0.99 0.99 0.99 1</specular>
        <emissive>0.2 0.2 0.2 1</emissive>
      </material> -->
    </visual>
    
    <collision name='caster_collision_2'>
      <!-- <pose>0.2 0 -0.225 0 0 0</pose> -->
      <origin rpy='0 0 0' xyz='0.2 0 -0.225'/>
      <geometry>
        <box size=".1 .1 .05">
          <!-- <size>.1 .1 .05</size> -->
        </box>
      </geometry>

      <surface>
        <friction>
          <ode>
            <mu>0.0</mu>
            <mu2>0.0</mu2>
            <slip1>0.0</slip1>
            <slip2>0.0</slip2>
          </ode>
        </friction>
      </surface>
    </collision>
    
    <visual name='caster_visual_2'>
      <!-- <pose>0.2 0 -0.2 0 0 0</pose> -->
      <origin rpy='0 0 0' xyz='0.2 0 0.05'/>
      <geometry>
        <sphere radius=".05">
          <!-- <radius>.05</radius> -->
        </sphere>
      </geometry>
      <material name="caster_gray">
        <color rgba="0.15 0.15 0.15 1"/>
      </material>
      <!-- <material>
        <ambient>0.15 0.15 0.15 1</ambient>
        <diffuse>0.25 0.25 0.25 1</diffuse>
        <specular>0.99 0.99 0.99 1</specular>
        <emissive>0.2 0.2 0.2 1</emissive>
      </material> -->
    </visual>
    
    
  </link>

  <link name="base_laser">
    <visual>
      <origin xyz="0 0 0" rpy="0 0 0"/>
      <geometry>
        <mesh filename="model://lidar2d/meshes/hokuyo.dae" />
      </geometry>
      <material name="dark"/>
    </visual>

    <collision>
      <origin xyz="0.015 0 -0.0065" rpy="0 0 0"/>
      <geometry>
        <cylinder length="0.0315" radius="0.055"/>
      </geometry>
    </collision>

    <inertial>
      <mass value="0.1" />
      <origin xyz="0 0 0" />
      <inertia ixx="0.001" ixy="0.0" ixz="0.0"
               iyy="0.001" iyz="0.0"
               izz="0.001" />
    </inertial>
  </link>

  
  <link name="left_wheel">
    <!-- <pose>0 0.27 0.125 0 1.5707 1.5707</pose> -->
    <origin rpy='0 1.5707 1.5707' xyz='0 0.27 0.125'/>

    <inertial>
      <origin xyz="0 0 0" />
      <mass value="2.8498940e-02" />
      <inertia ixx="1.1175580e-05" ixy="-4.2369783e-11" ixz="-5.9381719e-09"
               iyy="1.1192413e-05" iyz="-1.4400107e-11"
               izz="2.0712558e-05" />
    </inertial>
    
    <collision name="collision">
      <geometry>
        <cylinder radius="0.125" length="0.03">
          <!-- <radius>.125</radius>
          <length>.03</length> -->
        </cylinder>
      </geometry>
      <surface>
        <friction>
          <ode>
            <mu>0.8</mu>
            <mu2>0.8</mu2>
            <slip1>0.0</slip1>
            <slip2>0.0</slip2>
          </ode>
        </friction>
      </surface>
    </collision>
    <visual name="visual">
      <geometry>
       <cylinder radius="0.125" length="0.03">
          <!-- <radius>.125</radius>
          <length>.03</length> -->
        </cylinder>
      </geometry>
      <!-- <material>
        <ambient>0.01 0.01 0.01 1</ambient>
        <diffuse>0.15 0.15 0.15 1</diffuse>
        <specular>0.99 0.99 0.99 1</specular>
        <emissive>0.01 0.01 0.01 1</emissive>
      </material> -->
      <material name="wheel_black">
        <color rgba="0.01 0.01 0.01 1"/>
      </material>
    </visual>
  </link>

  
  <link name="right_wheel">
    <!-- <pose>0 -0.27 0.125 0 1.5707 1.5707</pose> -->
    <origin rpy='0 1.5707 1.5707' xyz='0 -0.27 0.125'/>
    
    <inertial>
      <origin xyz="0 0 0" />
      <mass value="2.8498940e-02" />
      <inertia ixx="1.1175580e-05" ixy="-4.2369783e-11" ixz="-5.9381719e-09"
               iyy="1.1192413e-05" iyz="-1.4400107e-11"
               izz="2.0712558e-05" />
    </inertial>

    <collision name="collision">
      <geometry>
        <cylinder radius="0.125" length="0.03">
          <!-- <radius>.125</radius>
          <length>.03</length> -->
        </cylinder>
      </geometry>
      <surface>
        <friction>
          <ode>
            <mu>0.8</mu>
            <mu2>0.8</mu2>
            <slip1>0.0</slip1>
            <slip2>0.0</slip2>
          </ode>
        </friction>
      </surface>
    </collision>
    <visual name="visual">
      <geometry>
        <cylinder radius="0.125" length="0.03">
          <!-- <radius>.125</radius>
          <length>.03</length> -->
        </cylinder>
      </geometry>
      <!-- <material>
        <ambient>0.01 0.01 0.01 1</ambient>
        <diffuse>0.15 0.15 0.15 1</diffuse>
        <specular>0.99 0.99 0.99 1</specular>
        <emissive>0.01 0.01 0.01 1</emissive>
      </material> -->
      <material name="wheel_black">
        <color rgba="0.01 0.01 0.01 1"/>
      </material>
    </visual>
  </link>

  <joint name="wheel_left_joint" type="continuous">
    <parent link="base_link"/>
    <child link="left_wheel"/>
    <origin xyz="0 0.27 0.125" rpy="0 1.5707 1.5707"/>
    <axis xyz="0 1 0"/>
  </joint>

  <joint name="wheel_right_joint" type="continuous">
    <parent link="base_link"/>
    <child link="right_wheel"/>
    <origin xyz="0 -0.27 0.125" rpy="0 1.5707 1.5707"/> 
    <axis xyz="0 1 0"/>
  </joint>

  <joint name="lidar2d_joint" type="fixed">
    <child link="base_laser"></child>
    <parent link="base_link"></parent>
    <origin xyz="0 0 0.45" rpy="0 0 0"/>
  </joint>

</robot>
